Workbook
Name Bienes_Biomasa_Biogás: Bienes!$A$4:$A$44
Name Bienes_Biomasa_Cultivos_energéticos: Bienes!$D$4:$D$30
Name Bienes_Biomasa_Gasificación: Bienes!$B$4:$B$32
Name Bienes_Biomasa_Generación_cogeneración: Bienes!$E$4:$E$51
Name Bienes_Biomasa_Pirolización: Bienes!$C$4:$C$39
Name Bienes_Eólica_Eólica: Bienes!$F$4:$F$37
Name Bienes_Geotérmica_Central_de_ciclo_binario: Bienes!$I$4:$I$51
Name Bienes_Geotérmica_Central_de_vapor_seco: Bienes!$G$4:$G$51
Name Bienes_Geotérmica_Central_flash: Bienes!$H$4:$H$51
Name Bienes_PCH_Hidráulica: Bienes!$J$4:$J$37
Name Bienes_PCH_Hidrocinética: Bienes!$K$4:$K$37
Name Bienes_Solar_Fotovoltaica: Bienes!$L$4:$L$42
Name NOMBRE: 'FORMATO 1'!$A$34
Name re: 'FORMATO 2'!$F$21
Name REC_Biomasa: Listas2!$F$5:$F$13
Name REC_Eólica: Listas2!$F$20
Name REC_Geotérmica: Listas2!$F$24
Name REC_PCH: Listas2!$F$28
Name REC_Solar: Listas2!$F$32
Name Servicios_Biomasa: Servicios!$A$4:$A$15
Name Servicios_Eólica: Servicios!$B$4:$B$13
Name Servicios_Geotérmica: Servicios!$C$4:$C$18
Name Servicios_PCH: Servicios!$D$4:$D$12
Name Servicios_Solar: Servicios!$E$4:$E$14
Name TEC_Biomasa: Listas2!$H$5:$H$9
Name TEC_Eólica: Listas2!$H$17
Name TEC_Geotérmica: Listas2!$H$22:$H$24
Name TEC_PCH: Listas2!$H$29:$H$30
Name TEC_Solar: Listas2!$H$35

Sheet FORMATO 1
D2: FORMATO SOLICITUD DE INCENTIVOS TRIBUTARIOS PARA PROYECTOS DE FNCE EXCLUSIÓN DE IVA, DEDUCCIÓN EN RENTA EXENCIÓN DE ARANCEL Y DEPRECIACIÓN ACELERADA | Y2: Código: : F-CT-01
Y3: Fecha: 04/12/2024
Y5: Versión: 03
A13: FORMATO 1 FORMATO ÚNICO DE SOLICITUD PARA INCENTIVOS A LA INVERSIÓN EN PROYECTOS DE FNCE (CAPÍTULO III DE LA LEY 1715 DE 2014)
A14: 1. SOLICITANTES
A15: 1.1 Solicitante Principal | P15: 1.2 Solicitante Secundario
A16: Nombre o razón social | P16: Nombre o razón social
A17: SUN FACTORY SAS ESP | P17: Solenium S.A.S
A18: Sector productivo | P18: Sector productivo | V18: Instalaciones Eléctricas
A19: Código CIIU | P19: Código CIIU | V19: 4321 - Instalaciones eléctricas
A20: Rol | P20: Rol | V20: Instalador
A21: C.C ó NIT | P21: C.C ó NIT | V21: 901097244-5
A22: Departamento | P22: Departamento | V22: ANTIOQUIA
A23: Municipio | G23: BOGOTÁ. D.C. | P23: Municipio | V23: MEDELLÍN
A24: Dirección | P24: Dirección | V24: CALLE 46 #70A-79
A25: Teléfono | P25: Teléfono | V25: (+57) 316 1935991
A26: Nombre del Representante Legal (R.L.) | P26: Nombre del Representante Legal (R.L.) | V26: Jaibet Paola Santiago Ribón
A27: C.C o C.E Representante Legal | P27: C.C o C.E Representante Legal | V27: 1152203750
A28: correo electrónico de notificación | P28: correo electrónico de notificación | V28: info@solenium.co
A29: CONTACTO | P29: CONTACTO
A30: Nombre de la persona de contacto | P30: Nombre de la persona de contacto | V30: Sergio Danny Camacho Guzman
A31: Teléfono de la persona de contacto | P31: Teléfono de la persona de contacto | V31: (+57) 301 2950511
A32: Correo Electrónico persona de contacto | P32: Correo Electrónico persona de contacto | V32: tramites@solenium.co
A33: 2. NOMBRE DEL PROYECTO DE FNCE
A34: MGS 0000
A36: 3. ETAPA DEL PROYECTO EN FNCE
A37: Inversión
A38: 4. INFORMACIÓN DE REGISTRO DEL PROYECTO
A39: Número de radicado del registro del proyecto expedido por la UPME (Si aplica) | R39: Fecha del radicado
A40: 5. INCENTIVOS A LOS CUALES APLICA (Marque con una X)
A41: Exclusión de IVA | D41: X | E41: Exención de Arancel | L41: X | M41: Deducción de Renta | T41: X | U41: Depreciación acelerada | AC41: X
A42: 6. LUGAR DE UBICACIÓN DE LA INVERSION
A44: Departamento | F44: Antioquia | P44: Municipio | T44: Titiribí
A46: 7. VALOR DE LA INVERSION OBJETO DEL BENEFICIO ANTES DE IMPUESTOS
A47: Valor total en COP
A48: 8. NÚMERO DE ACREDITACIÓN O REFERENCIA DE PAGO DE LA TARIFA
A49: Número de referencia de pago (CUS)
A50: 9. DECLARACIÓN
A51: Con la presente solicitud declaro que toda la información suministrada con miras a obtener la certificación que permita acceder a los incentivos establecidos en los artículos 11, 12, 13 y 14 de la Ley 1715 de 2014, modificados por la Ley 2099 de 2021, es veraz y me hago responsable por ella. Así mismo, autorizo a la UPME para que de conformidad con el artículo 67 del Código de Procedimiento Administrativo y de lo Contencioso Administrativo, notifique todas las actuaciones surtidas en desarrollo del trámite al correo electrónico de notificaciones informado en el presente documento.
B56: Firma del R.L. del solicitante principal | Q56: Firma del R.L. del solicitante secundario
...

Sheet FORMATO 2
C2: FORMATO SOLICITUD DE INCENTIVOS TRIBUTARIOS PARA PROYECTOS DE FNCE EXCLUSIÓN DE IVA, DEDUCCIÓN EN RENTA EXENCIÓN DE ARANCEL Y DEPRECIACIÓN ACELERADA | T2: Código: F-CT-01
T3: Fecha: 10/10/2024
T5: Versión: 03
A14: FORMATO 2 GENERALIDADES DEL PROYECTO DE FNCE (CAPÍTULO III DE LA LEY 1715 DE 2014)
A16: 1. INFORMACIÓN GENERAL DEL PROYECTO DE FNCE
A17: Nombre del proyecto | F17: =NOMBRE -> MGS 0000
A18: Sector donde se realizará el proyecto | F18: Generación eléctrica
A19: Tipo de generador | F19: Generador
A20: Tipo de FNCE (Ley 1715 de 2014) | F20: Solar
A21: Recurso Energético | F21: Sol
L22: Relacionar Cual
A23: Tecnología | F23: Fotovoltaica
F24: Otra | L24: Relacionar Cual
A25: Ubicación | F25: Departamento
F26: Municipio
F27: Zona | L27: SIN
A28: 2. INFORMACIÓN TÉCNICA
A29: Datos técnicos | F29: Área del Proyecto (m2)
F30: Capacidad Instalada (kW)
F31: Energía Generada (kWh/año)
F32: Vida útil del proyecto (años)
F33: Eficiencia de la planta (%)
F34: Factor de Planta (%)
A35: Datos de Conexión | F35: ¿Se conectará a la red? | N35: Si
F36: Nivel de tensión (kV) (Cuando aplique)
F37: Nombre del Operador de Red (Cuando aplique) | N37: AIR-E
A38: 3. PERIODO DE EJECUCIÓN
A39: Periodo de Ejecución | F39: Fecha estimada de inicio de construcción | N39: 45667
F40: Fecha estimada de entrada en operación comercial
A41: 4. INFORMACIÓN ECONÓMICA
A42: Datos Económicos | F42: Costo total del proyecto antes de IVA (COP)
F43: IVA del proyecto (COP)
F44: Costo de generación sin el proyecto (COP/kWh) (Cuando aplique)
A45: 5. DESCRIPCIÓN DEL PROYECTO

Sheet FORMATO 3
C2: FORMATO SOLICITUD DE INCENTIVOS TRIBUTARIOS PARA PROYECTOS DE FNCE EXCLUSIÓN DE IVA, DEDUCCIÓN EN RENTA EXENCIÓN DE ARANCEL Y DEPRECIACIÓN ACELERADA | M2: Código: F-CT-01
M3: Fecha: 10/10/2024
M5: Versión: 03
A10: FORMATO 3 FORMATO DE ESPECIFICACIONES DE ELEMENTOS, EQUIPOS Y/O MAQUINARIA (CAPÍTULO III DE LA LEY 1715 DE 2014)
A11: Ítem | B11: Nombre del Elemento/Equipo/Maquinaria | C11: Subpartida arancelaria | D11: Cantidad | E11: Unidad de Medida | F11: Marca | G11: Modelo / Referencia | H11: Normas técnicas | I11: Fabricante | J11: Proveedor | K11: Valor total en COP (Sin incluir IVA) | L11: Valor IVA en COP | M11: Función | N11: Soporte | O11: Certificado de Conformidad de Producto | P11: Odoo ID
A12: 1 | B12: Subestación o Power Station | C12: 8504.34.10.00 | D12: 1 | E12: unidades | F12: ZENTRACK | G12: CN-1250/012 | H12: EN61000-6:2019; EN61000-6-4:2019; IEC 61558- 1:2019; IEC 62271-202:2022; IEC 61330:1995 | I12: EAGLERISE ELECTRIC & ELECTRONIC (CHINA) CO. LTD | J12: NEXUS TRADE CONSULTING LIMITED | K12: 577362000 | L12: =K12*0.19 -> 109698780 | M12: La subestación compacta para intemperie transforma la energía generada en baja tensión por el proyecto fotovoltaico a media tensión, permitiendo su integración a la red de distribución local. Cuenta con centros de transformación, celdas de medida y protección, y dispositivos contra sobrecorriente y sobrevoltaje. Su función es esencial para suministrar energía a los habitantes cercanos. | N12: https://drive.google.com/drive/folders/149PiE67rtKaDRx-CQfP_LsUKNH8RPryo | P12: No encontrado
A13: 2 | B13: Subestación o Power Station | C13: 8504.34.10.00 | D13: 1 | E13: unidades | F13: ZENTRACK | G13: CN-1250/015 | H13: EN61000-6:2019; EN61000-6-4:2019; IEC 61558-1:2019; IEC 62271-202:2022; IEC 61330:1995 | I13: EAGLERISE ELECTRIC & ELECTRONIC (CHINA) CO. LTD | J13: NEXUS TRADE CONSULTING LIMITED | K13: 7.1312284e+08 | L13: $135.493.339,59 | M13: La subestación compacta para intemperie transforma la energía generada en baja tensión por el proyecto fotovoltaico a media tensión, permitiendo su integración a la red de distribución local. Cuenta con centros de transformación, celdas de medida y protección, y dispositivos contra sobrecorriente y sobrevoltaje. Su función es esencial para suministrar energía a los habitantes cercanos. | N13: https://drive.google.com/drive/folders/1BZTPlrGbiOcKSSlGhOfzdjAdnugKSXtF | P13: No encontrado
A14: 3 | B14: Subestación o Power Station | C14: 85.04.22.90.00 | D14: 1 | E14: unidades | F14: ZENTRACK | G14: CN-1100/022 | H14: EN61000-6:2019; EN61000-6-4:2019; IEC 61558-1:2019; IEC 62271-202:2022; IEC 61330:1995 | I14: EAGLERISE ELECTRIC & ELECTRONIC (CHINA) CO. LTD | J14: ZENTRACK | K14: 577362000 | L14: =K14*0.19 -> 109698780 | M14: La subestación compacta para intemperie transforma la energía generada en baja tensión por el proyecto fotovoltaico a media tensión, permitiendo su integración a la red de distribución local. Cuenta con centros de transformación, celdas de medida y protección, y dispositivos contra sobrecorriente y sobrevoltaje. Su función es esencial para suministrar energía a los habitantes cercanos. | N14: https://drive.google.com/drive/folders/1cc5cpb9x2xwyAoBBs67LEUqpqbe4cNCu | P14: P01931
A15: 4 | B15: Subestación o Power Station | C15: 85.04.22.90.00 | D15: 1 | E15: unidades | F15: ZENTRACK | G15: CN-1100/025 | H15: EN61000-6:2019; EN61000-6-4:2019; IEC 61558-1:2019; IEC 62271-202:2022; IEC 61330:1995 | I15: EAGLERISE ELECTRIC & ELECTRONIC (CHINA) CO. LTD | J15: ZENTRACK | K15: 593808411 | L15: =K15*0.19 -> 1.128236e+08 | M15: La subestación compacta para intemperie transforma la energía generada en baja tensión por el proyecto fotovoltaico a media tensión, permitiendo su integración a la red de distribución local. Cuenta con centros de transformación, celdas de medida y protección, y dispositivos contra sobrecorriente y sobrevoltaje. Su función es esencial para suministrar energía a los habitantes cercanos. | N15: https://drive.google.com/drive/folders/184IyEgfQEVb0mxUHFCwhbcytQbdnM25v | P15: No encontrado
A16: 5 | B16: Seguidores solares | C16: 7308.90.90.00 | D16: 18 | E16: unidades | F16: ZENTRACK | G16: Tracker 1P Singsun | H16: ISO 9001, ISO 14001, ISO 1461 | I16: JIANGSU GUOQIANG SINGSUN ENERGY CO., LTD | J16: ZENTRACK | K16: =K14*0.85 -> 490757700 | L16: =K16*0.19 -> 93243963 | M16: Estructura móvil instalada para soportar los módulos fotovoltaicos y para seguir la trayectoria del sol. | N16: https://drive.google.com/drive/folders/13HHTDddZaBxA5miHhexjxiByePe9BqxS | P16: P00575
A17: 6 | B17: Seguidores solares | C17: 7308.90.90.00 | D17: 18 | E17: unidades | F17: ZENTRACK | G17: Tracker 2P Singsun | H17: ISO 9001, ISO 14001, ISO 1461 | I17: JIANGSU GUOQIANG SINGSUN ENERGY CO., LTD | J17: ZENTRACK | K17: =K15*0.85 -> 5.0473715e+08 | L17: =K17*0.19 -> 95900058 | M17: Estructura móvil instalada para soportar los módulos fotovoltaicos y para seguir la trayectoria del sol. | N17: https://drive.google.com/drive/folders/1LGlr0snTHTDmlIvybUh5fmdkNjI15f5y | P17: P00576
A18: 7 | B18: Unidad funcional | C18: 8479.89.90.00 | D18: 20 | E18: unidades | F18: TrinaTracker | G18: Vanguard -2P | H18: UL 3703, UL 2703, IEC 62817, ISO 9001, ISO14001 | I18: Trina Solar Co.,Ltd | J18: Trina Solar Co.,Ltd | K18: 500428320 | L18: =K18*0.19 -> 95081381 | M18: Soporte estructural para los paneles solares con un sistema de "tracking" que le permite girar sobre su eje transversal para seguir el sol, el equipo fue clasificado arancelariamente como una unidad funcional por la Dirección de Impuestos y Aduanas Nacionales | N18: https://drive.google.com/drive/folders/13R5ydcDZsTgU9S9CVxafW9PKXeEsitjV?usp=drive_link | P18: P00576
A19: 8 | B19: Unidad funcional | C19: 8479.89.90.00 | D19: 20 | E19: unidades | F19: Zentrack | G19: Tracker 1P Singsun | H19: ISO 9001, ISO 14001, ISO 1461 | I19: JIANGSU GUOQIANG SINGSUN ENERGY CO., LTD | J19: ZENTRACK | K19: =K17*0.85 -> 4.2902658e+08 | L19: =K19*0.19 -> 81515050 | M19: Soporte estructural para los paneles solares con un sistema de "tracking" que le permite girar sobre su eje transversal para seguir el sol, el equipo fue clasificado arancelariamente como una unidad funcional por la Dirección de Impuestos y Aduanas Nacionales | N19: https://drive.google.com/drive/folders/1rzFaWfqPq962WWIfcZTMSwxV9pyxXJao | P19: P00575
A20: 9 | B20: Sistema de monitoreo, control y automatización | C20: 9032.89.90.00 | D20: 19 | E20: unidades | F20: ZENTRACK | G20: CONTROLADOR SEGUIDOR SOLAR V1R3 | H20: ISO 9001 UL (E332411) | I20: H.C.C. International Limited | J20: ZENTRACK SAS | K20: =K12*0.15 -> 86604300 | L20: =K20*0.19 -> 16454817 | M20: Controladores Zentrack, estos equipos se encargan de realizar el control de los motores utilizados para posicionar en posición perpendicular al sol el seguidor solar que soporta los paneles solares. El controlador calcula la trayectoria del sol y con un sensor de inclinación integrado posiciona la estructura para seguir el sol. Hace parte esencial del sistema de seguimiento solar | N20: https://drive.google.com/drive/folders/1rzFaWfqPq962WWIfcZTMSwxV9pyxXJao | P20: No encontrado
A21: 10 | B21: Paneles/modulos o celdas fotovoltaicas | C21: 8541.43.00.00 | D21: 994 | E21: unidades | F21: LONGi | G21: LR5-72HGD-580M | H21: IEC61215, IEC61730, UL61730, IEC62941 | I21: LONGi | J21: LONGi | K21: 1.1081705e+09 | L21: =0 -> 0 | M21: Principal componente del sistema de energía solar y su función es transformar la radiación solar directamente en electricidad | N21: https://drive.google.com/drive/folders/1v5PFo_rL5WEAQ9DsjzwtKHaQqFWCfoNn | P21: P00771
A22: 11 | B22: Paneles/modulos o celdas fotovoltaicas | C22: 8541.43.00.00 | D22: 2206 | E22: unidades | F22: LONGi | G22: LR7-72HGD610M | H22: IEC61215, IEC61730, UL61730, IEC62941 | I22: LONGi | J22: LONGi | K22: 1.1081705e+09 | L22: =0 -> 0 | M22: Principal componente del sistema de energía solar y su función es transformar la radiación solar directamente en electricidad | N22: https://drive.google.com/drive/folders/1W0chWWJxQITFQX8qZPlnjboQTzuztD1F | P22: P01666
A23: 12 | B23: Paneles/modulos o celdas fotovoltaicas | C23: 8541.43.00.00 | D23: 2032 | E23: unidades | F23: LONGi | G23: LR7-72HYD-650M | H23: IEC61215, IEC61730, UL61730, IEC62941 | I23: LONGi | J23: LONGi | K23: 1.1081705e+09 | L23: =0 -> 0 | M23: Principal componente del sistema de energía solar y su función es transformar la radiación solar directamente en electricidad | N23: https://drive.google.com/drive/folders/1Xzeum8R9QMY_Y8iTd8-rQO30BLzR3Cru | P23: P00773
A24: 13 | B24: Paneles/modulos o celdas fotovoltaicas | C24: 8541.43.00.00 | D24: 2196 | E24: unidades | F24: LONGi | G24: LR7-72HGD-615M | H24: IEC61215, IEC61730, UL61730, IEC62941 | I24: LONGi | J24: LONGi | K24: 1.1081705e+09 | L24: =0 -> 0 | M24: Principal componente del sistema de energía solar y su función es transformar la radiación solar directamente en electricidad | N24: https://drive.google.com/drive/folders/1W0chWWJxQITFQX8qZPlnjboQTzuztD1F | P24: P01526
A25: 14 | B25: Paneles/modulos o celdas fotovoltaicas | C25: 8541.43.00.00 | D25: 2032 | E25: unidades | F25: LONGi | G25: LR8-66HVD-655M | H25: IEC61215, IEC61730, UL61730, IEC62941 | I25: LONGi | J25: LONGi | K25: 1.1081705e+09 | L25: =0 -> 0 | M25: Principal componente del sistema de energía solar y su función es transformar la radiación solar directamente en electricidad | N25: https://drive.google.com/drive/folders/19efuYBKjM8Oh-ZfVDbMFTiX1XJq4P8ez | P25: P01667
A26: 15 | B26: Paneles/modulos o celdas fotovoltaicas | C26: 8541.43.00.00 | D26: 2032 | E26: unidades | F26: LONGi | G26: LR8-66HGD-615M | H26: IEC61215, IEC61730, UL61730, IEC62941 | I26: LONGi | J26: LONGi | K26: 1.1081705e+09 | L26: =0 -> 0 | M26: Principal componente del sistema de energía solar y su función es transformar la radiación solar directamente en electricidad | N26: https://drive.google.com/drive/folders/14zrIbdPCsxdJuhHTGBpgY2jL9lzFebsN | P26: P01526
A27: 16 | B27: Paneles/modulos o celdas fotovoltaicas | C27: 8541.43.00.00 | D27: 2032 | E27: unidades | F27: LONGi | G27: LR8-66HYD-655M | H27: IEC61215, IEC61730, UL61730, IEC62941 | I27: LONGi | J27: LONGi | K27: 1.1081705e+09 | L27: =0 -> 0 | M27: Principal componente del sistema de energía solar y su función es transformar la radiación solar directamente en electricidad | N27: https://drive.google.com/drive/folders/1rsZFZeulPRCYwiMXlaM-GcvB3vIGGO3x | P27: P01667
A28: 17 | B28: Paneles/modulos o celdas fotovoltaicas | C28: 8541.43.00.00 | D28: 2032 | E28: unidades | F28: LONGi | G28: LR7-72HGD 620M | H28: IEC61215, IEC61730, UL61730, IEC62941 | I28: LONGi | J28: LONGi | K28: 1.1081705e+09 | L28: =0 -> 0 | M28: Principal componente del sistema de energía solar y su función es transformar la radiación solar directamente en electricidad | N28: https://drive.google.com/drive/folders/1W0chWWJxQITFQX8qZPlnjboQTzuztD1F | P28: P01527
A29: 18 | B29: Inversores o microinversores (Off Gid, Grid Tie o Híbrido) | C29: 8504409090 | D29: 4 | E29: unidades | F29: Huawei | G29: SUN2000-247.5KTL-H1 | H29: IEC 61727:2004; IEC 62116:2014 | I29: Huawei Technologies Co., Ltd. | J29: HUAWEI INTERNATIONAL CO LIMITED | K29: 1.0355318e+08 | L29: 19675105 | M29: Transformacion de energia DC/AC | N29: https://drive.google.com/drive/folders/1uzr6NJKRStMhnDDofeFaPjLjh0KdD8f5 | O29: https://drive.google.com/drive/folders/1RRBxfJPuzZMLRVIzMTb4NSErLaOxCt5w | P29: P01243
A30: 19 | B30: Inversores o microinversores (Off Gid, Grid Tie o Híbrido) | C30: 8504409090 | D30: 4 | E30: unidades | F30: Huawei | G30: SUN2000-249KTL-H1 | H30: IEC 61727:2004; IEC 62116:2014 | I30: Huawei Technologies Co., Ltd. | J30: HUAWEI INTERNATIONAL CO LIMITED | K30: 1.0355318e+08 | L30: 19675105 | M30: Transformacion de energia DC/AC | N30: https://drive.google.com/drive/folders/1IYQfLVwNswfcGO-dKZOEcPAWXMJShUL_ | O30: https://drive.google.com/drive/folders/1RRBxfJPuzZMLRVIzMTb4NSErLaOxCt5w | P30: P01243
A31: 20 | B31: Inversores o microinversores (Off Gid, Grid Tie o Híbrido) | C31: 8504409090 | D31: 3 | E31: Unidades | F31: Huawei | G31: SUN2000-330KTL-H1 | H31: IEC 61727:2004 Photovoltaic (PV) systems – Characteristics of the utility interface IEC 62116:2014 Test procedure of islanding prevention measures for utilityinterconnected photovoltaic inverters | I31: Huawei Technologies Co., Ltd. | J31: HUAWEI INTERNATIONAL CO LIMITED | K31: 100730645 | L31: =K31*0.19 -> 19138823 | M31: Transformación de energía DC/AC | N31: https://drive.google.com/drive/folders/1XVHXVNZhsQLqJm55cowRAr7WgAyCuGG9 | P31: P00655
A32: 21 | B32: Inversores o microinversores (Off Gid, Grid Tie o Híbrido) | C32: 8504409090 | D32: 1 | E32: unidades | F32: Huawei | G32: SUN2000-40KTL-M3 | H32: EN 62109-1/-2, IEC 62109-1/-2, EN 50530, IEC 62116, IEC 60068, IEC 61683 | I32: Huawei Technologies Co., Ltd. | J32: HUAWEI INTERNATIONAL CO LIMITED | K32: 10190450 | L32: =K32*0.19 -> 1936185.5 | M32: Transformación de energía DC/AC | N32: https://drive.google.com/drive/folders/1aYvYiIGK0bLmaslxX5eWDsY5gIgAxGE5 | P32: P00656
A33: 22 | B33: Inversores o microinversores (Off Gid, Grid Tie o Híbrido) | C33: 8504409090 | D33: 1 | E33: Unidades | F33: Huawei | G33: SUN2000-50KTL-M3 | H33: EN 62109-1/-2, IEC 62109-1/-2, EN 50530, IEC 62116, IEC 60068, IEC 61683, IEC 61727, ABNT NBR 16149, ABNT NBR 16150, ABNT NBR IEC 62116 | I33: Huawei Technologies Co., Ltd. | J33: HUAWEI INTERNATIONAL CO LIMITED | K33: 12504680 | L33: =K33*0.19 -> 2375889.2 | M33: Transformación de energía DC/AC | N33: https://drive.google.com/drive/folders/1u2EMBQNnKkj1JWL4zsJCQgYfEQb8s4QG | P33: P00657
A34: 23 | B34: Datalogger | C34: 851762200 | D34: 1 | E34: unidad | F34: Huawei | G34: SmartLogger3000A01AU | H34: IEC 60870-5-104, IEC 60870-5-103 | I34: Huawei Technologies Co., Ltd. | J34: HUAWEI INTERNATIONAL CO LIMITED | M34: Datalogger para la supervisión, control y adquisición de datos del sistema fotovoltaico, necesario para la integración con sistemas de monitoreo y cumplimiento de protocolos de comunicación exigidos (IEC 60870-5-104 / 103), permitiendo la gestión de inversores y operación remota del sistema | N34: https://drive.google.com/drive/folders/17nqi9n1BchtoHKfbCfSFiqh2-gNWBx-3 | P34: P01775
A35: 24 | B35: Datalogger | C35: 851762200 | D35: 1 | E35: unidad | F35: Huawei | G35: SmartLogger3000A03EU | H35: IEC 60870-5-104, IEC 60870-5-103 | I35: Huawei Technologies Co., Ltd. | J35: HUAWEI INTERNATIONAL CO LIMITED | M35: Datalogger para la supervisión, control y adquisición de datos del sistema fotovoltaico, necesario para la integración con sistemas de monitoreo y cumplimiento de protocolos de comunicación exigidos (IEC 60870-5-104 / 103), permitiendo la gestión de inversores y operación remota del sistema | N35: https://drive.google.com/drive/folders/17nqi9n1BchtoHKfbCfSFiqh2-gNWBx-3 | P35: P01910
A36: 25 | B36: Conectores MC4 | D36: 200 | E36: unidades | F36: Weidmüller | G36: BUGH WM4 C BT | H36: DIN EN 50521, IEC 62852 | I36: Weidmüller Interface GmbH & Co. KG | J36: Weidmüller Interface GmbH & Co. KG | M36: Conectores que facilitan la conexión de los paneles fotovoltaicos | N36: https://drive.google.com/drive/folders/1-2SDtnilKVkzbzm9670h4Q6m2h67DLEr | P36: P00458
A37: 26 | B37: Conectores MC4 | D37: 200 | E37: unidades | F37: Weidmüller | G37: BUKO WM4 C BT | H37: DIN EN 50521 | I37: Weidmüller Interface GmbH & Co. KG | J37: Weidmüller Interface GmbH & Co. KG | M37: Conectores que facilitan la conexión de los paneles fotovoltaicos | N37: https://drive.google.com/drive/folders/1amUHJ6EEV4uoBb1yKnPdglVV4cfaXurS | P37: P00806
A38: 27 | B38: Conectores MC4 | D38: 200 | E38: unidades | F38: Weidmüller | G38: SFGH WM4 C BT | H38: DIN EN 50521, IEC 62852 | I38: Weidmüller Interface GmbH & Co. KG | J38: Weidmüller Interface GmbH & Co. KG | M38: Conectores que facilitan la conexión de los paneles fotovoltaicos | N38: https://drive.google.com/drive/folders/1OJ3kxVxw9yhyVvPcj4lAtZVRvI6UtXs_ | P38: P00461
A39: 28 | B39: Conectores MC4 | D39: 200 | E39: unidades | F39: Weidmüller | G39: SFkO WM4 C BT | H39: DIN EN 50521 | I39: Weidmüller Interface GmbH & Co. KG | J39: Weidmüller Interface GmbH & Co. KG | M39: Conectores que facilitan la conexión de los paneles fotovoltaicos | N39: https://drive.google.com/drive/folders/1Fp0aiedr33njv9LVd2JC0tg1MAvEB5L_ | P39: P00807
A40: 29 | B40: Interruptores, reconectadores, seccionadores y transferencias automáticas | D40: 1 | E40: Unidad | F40: Noja | G40: OSM-15-12-630 | H40: ANSI C37.60-2012, IEC 61850, IEC 60870-5-101, IEC 60870-5-104, DNP3, IEC 61499, IEC 255, IP66, IP65 | I40: Noja Power Switchgear Pty. Ltd. | J40: Potencia y Tecnologías Incorporadas S.A.S | M40: Equipo encargado de proteger el sistema de generación en media tensión | N40: https://drive.google.com/drive/folders/1Z1p6iVbf8ZfNUNKctMlV-gTfT9a90dUO | P40: P00836
A41: 30 | B41: Interruptores, reconectadores, seccionadores y transferencias automáticas | D41: 1 | E41: Unidad | F41: Noja | G41: OSM27 | H41: ANSI C37.60-2012, IEC 61850, IEC 60870-5-101, IEC 60870-5-104, DNP3, IEC 61499, IEC 255, IP66, IP65 | I41: Noja Power Switchgear Pty. Ltd. | J41: Potencia y Tecnologías Incorporadas S.A.S | M41: Equipo encargado de proteger el sistema de generación en media tensión | N41: https://drive.google.com/drive/folders/1Z1p6iVbf8ZfNUNKctMlV-gTfT9a90dUO | P41: No encontrado
A42: 31 | B42: Interruptores, reconectadores, seccionadores y transferencias automáticas | D42: 1 | E42: Unidad | F42: Noja | G42: OSM38 | H42: ANSI C37.60-2012, IEC 61850, IEC 60870-5-101, IEC 60870-5-104, DNP3, IEC 61499, IEC 255, IP66, IP65 | I42: Noja Power Switchgear Pty. Ltd. | J42: Potencia y Tecnologías Incorporadas S.A.S | M42: Equipo encargado de proteger el sistema de generación en media tensión | N42: https://drive.google.com/drive/folders/1Z1p6iVbf8ZfNUNKctMlV-gTfT9a90dUO | P42: No encontrado
A43: 32 | B43: Interruptores, reconectadores, seccionadores y transferencias automáticas | D43: 1 | E43: Unidad | F43: ABB | G43: OVR-15 | H43: IEC 62271-111 / IEEE C37.60:2012; IEC C37.100.1-2007 | I43: ABB India Limited | J43: ABB | M43: Equipo de protección, maniobra y reconexión automática en redes eléctricas de media tensión. Permite interrumpir corrientes de falla, realizar secuencias de apertura y recierre, proteger la red de distribución y mejorar la continuidad y confiabilidad del sistema eléctrico asociado al proyecto. | N43: https://drive.google.com/drive/folders/130FN_7LTt8PzogdEZa6eTOhOl920Wfrj | P43: P01774
A44: 33 | B44: Interruptores, reconectadores, seccionadores y transferencias automáticas | D44: 1 | E44: Unidad | F44: ABB | G44: OVR-27 | H44: IEC 62271-111 / IEEE C37.60:2012; IEC C37.100.1-2007 | I44: ABB India Limited | J44: ABB | M44: Equipo de protección, maniobra y reconexión automática en redes eléctricas de media tensión. Permite interrumpir corrientes de falla, realizar secuencias de apertura y recierre, proteger la red de distribución y mejorar la continuidad y confiabilidad del sistema eléctrico asociado al proyecto. | N44: https://drive.google.com/drive/folders/130FN_7LTt8PzogdEZa6eTOhOl920Wfrj | P44: No encontrado
A45: 34 | B45: Interruptores, reconectadores, seccionadores y transferencias automáticas | D45: 1 | E45: Unidad | F45: ABB | G45: OVR-38 | H45: IEC 62271-111 / IEEE C37.60:2012; IEC C37.100.1-2007 | I45: ABB India Limited | J45: ABB | M45: Equipo de protección, maniobra y reconexión automática en redes eléctricas de media tensión. Permite interrumpir corrientes de falla, realizar secuencias de apertura y recierre, proteger la red de distribución y mejorar la continuidad y confiabilidad del sistema eléctrico asociado al proyecto. | N45: https://drive.google.com/drive/folders/130FN_7LTt8PzogdEZa6eTOhOl920Wfrj | P45: P01773
A46: 35 | B46: Interruptores, reconectadores, seccionadores y transferencias automáticas | D46: 1 | E46: unidad | F46: ROCKWILL | G46: RCW15/630, Corriente Nominal Cortocircuito 15 kA. | H46: IEC 62271-200:2021, IEC 61439-3:2012, IEC 61439-1:2020, UL 969:2023, IEC 60695-11-10:2013 | I46: Wenzhou Rockwill Electric Co., Ltd | J46: ACOVIS Ingeníeria De Colombia SAS | M46: Equipo encargado de proteger el sistema de generación en media tensión | N46: https://drive.google.com/drive/folders/1WQcos9JHcWphjLlluEt1u6QqWwPv16T6 | P46: P00837
...

Sheet FORMATO 4
C2: FORMATO SOLICITUD DE INCENTIVOS TRIBUTARIOS PARA PROYECTOS DE FNCE EXCLUSIÓN DE IVA, DEDUCCIÓN EN RENTA EXENCIÓN DE ARANCEL Y DEPRECIACIÓN ACELERADA | F2: Código: F-CT-01
F3: Fecha: 10/10/2024
F5: Versión: 03
A11: FORMATO 4 FORMATO DE ESPECIFICACIONES DE SERVICIOS (CAPÍTULO III DE LA LEY 1715 DE 2014)
A12: Ítem | B12: Servicio | C12: Proveedor | D12: Alcance | E12: Valor total en COP (Sin incluir IVA) | F12: Valor IVA en COP
A13: 1 | B13: Asesoría y consultoría técnica | C13: ENEXA | D13: El presente servicio corresponde a la ejecución de Ensayos Pull Out Test (POT), estudio técnico indispensable para la validación de las condiciones geomecánicas del terreno en donde se instalará el sistema fotovoltaico. Este estudio resulta necesario para garantizar la viabilidad estructural del proyecto, dado que permite verificar la capacidad de carga y comportamiento del suelo en el sitio exacto de implantación de los paneles solares. Se realizará el Pull out test proyecto MOMPOX NORTE, ensayos a tracción, compresión y lateral 3 perfiles tipo IPE 180 por 3.5 metros de longitud, y 3 perfiles tipo IPE 200 por 3.5 metros de longitud. Procedimiento a aplicar segun especificaciones técnicas de ZentrackSe Hincarán 6 perfiles, 3 perfiles IPE 180 X 3.5m y 3 perfiles IPE 200 X 3.5m, de estas se escogen (2 UND) para las pruebas saturadas | F13: =E13*0.19 -> 0
A14: 2 | B14: Diseño e ingeniería del sistema | C14: Solenium S.A.S | D14: Medición de curvas IV, Verificación de Voltaje de Circuito Abierto Voc y Corriente de Corto Circuito Isc en mini granja solar MGS 0044, ubicada en Santa cruz del Mompox, Bolivar.
A15: 3 | B15: Diseño e ingeniería del sistema | C15: Solenium S.A.S | D15: NGENIERÍA DEL PROYECTO, INCLUYE: Diagrama unifilar, estudio de resistividad del suelo, estudio de conexión, planos de disposición física de la estructura, inversores, paneles y acometidas, plano de conexión de paneles y demás planos necesarios en la etapa de ingeniería de detalle del proyecto | F15: =E15*0.19 -> 0
A16: 4 | B16: Construcción de obras civiles y estructurales para el montaje del sistema. | C16: Solenium S.A.S | D16: El servicio de hincado corresponde a la instalación de las bases del seguidor solar o tracker sobre el cual se soportarán los paneles solares y se moverán para seguir la trayectoria del sol. | F16: =E16*0.19 -> 0
A17: 5 | B17: Instalación, montaje y puesta en operación del sistema. | C17: Solenium S.A.S | D17: 1.Ensayo VLF en terna de Cables de Media Tensión 2.Prueba de Resistencia de aislamiento en acometidas AC y DC. Este servicio hace parte del comisionamiento, permite verificar el correcto aislamiento de los cables a utilizar en el proyecto. | F17: =E17*0.19 -> 0
A18: 6 | B18: Certificación RETIE | C18: Certeam S.A.S | D18: Certificación de instalaciones eléctricas de acuerdo con el Reglamento Técnico de Instalaciones Eléctricas – RETIE (resolución 90708 de 2013) PROYECTO: MGS-0040 LA CACICA, ubicado en VEREDA GLOBO LA VEGA, VALLEDUPAR, CÉSAR. Certificación RETIE de las instalaciones eléctricas de sistema solar fotovoltaico, alimentadores en DC y AC, Centro de Transformación, Red MT Subterránea hasta punto de conexión o transición aéreasubterránea (donde aplique). Incluye revisión del sistema de puesta a tierra, apantallamiento, servicios auxiliares asociados a la planta, entre otros equipos. | E18: $ 5.300.000,00 | F18: $ 1.007.000,00
A19: 7 | B19: Asesoría y consultoría técnica | C19: Negawatt | D19: VERIFICACION Y CERTIFICACION DE LA FRONTERA DE GENERACIÓN MGS 0040-LA CACICA, UBICADA EN VEREDA GLOBO LA VEGA , ARRIBA DE VALLEDUPAR CESAR, CON PROPOSITOS DE CUMPLIR CON LOS REQUISITOS ESTABLECIDOS EN EL CÓDIGO DE MEDIDA PARA ENTRADA COMERCIAL AL SISTEMA Y CUYOS ALCANCES INCLUYE: CUMPLIMIENTO O NO DE LA RESOLUCION CREG 038 DE 2014, MEDIANTE LA CORROBORACION DE LAS CONFORMIDADES EN LOS SISTEMAS DE MEDICION, COMUNICACIONES, TELEMEDICION HACIA LOS CENTROS DE GESTION DE MEDIDAS, SEGURIDAD INFORMATICA Y DE ACCESO. ESTA VERIFICACION SE HARA UTILIZANDO EL PROCEDIMIENTO SEÑALADO EN LA CIRCULAR 098 DEL 13 DE NOVIEMBRE DE 2014. | E19: $ 4.600.000,00 | F19: $ 87.400.000,00
A20: 8 | B20: Instalación, montaje y puesta en operación del sistema. | C20: Transefi S.A.S. | D20: "Pruebas de Relación de transformación (TTR) y de resistencia de devanados, en la posición del conmutador en que se encuentran, a tres transformadores de las siguientes características: trafo 1.25MVA – 13.8kV/800V, trafo de 1.1kVA – 800V/480V y trafo de SSAA. Estas pruebas permiten asegurar que los transformadores proporcionan la relación de voltaje correcta y funcionen de manera eficiente y segura. Verificar que no se tengan malas condiciones eléctricas que puedan generar una afectación a la red de distribución a la que se van a conectar y asegurarse de que no existen cortos ni errores en las conexiones dentro de los transformadores." | E20: $ 3.800.000,00 | F20: $ 722.000,00
A21: 9 | B21: Instalación, montaje y puesta en operación del sistema. | C21: Quimaldi Instruments S.A.S | D21: Análisis termográfico con dron (Pilotaje + informe). Mediante la inspección termográfica con drones se pueden detectar fallos o puntos calientes existentes en un panel solar a causa de un exceso de calentamiento en una unión, en la misma celda o en el cableado y de no corregirse, llegará a averiar la celda o el cableado. En el peor de los casos, puede derivar en un cortocircuito y sus posibles complicaciones como un incendio. y Termografías en transformadores, tableros, inversores. Permite evaluar el correcto funcionamiento de los tableros eléctricos y equipos y detectar puntos calientes, lo que indica que se está presentando una falla, que está circulando un exceso de corriente por algún motivo y que debe corregirse para que el proyecto opere adecuadamente y no se presenten averías o cortocircuitos. Estos servicios hacen parte del comisionamiento. | E21: $ 5.000.000,00 | F21: $ 950.000,00
A22: 11 | B22: Construcción de obras civiles y estructurales para el montaje del sistema. | C22: Solenium S.A.S. | D22: El servicio de hincado corresponde a la instalación de las bases del seguidor solar o tracker sobre el cual se soportarán los paneles solares y se moverán para seguir la trayectoria del sol. Estas bases o hincas serán instaladas con hincadora hidráulica de 1200 J, mediante la presión controlada y la inserción progresiva en el suelo. | E22: $ 234.300.000,00 | F22: $ 44.517.000,00
A23: 13 | B23: Instalación, montaje y puesta en operación del sistema. | C23: ELECTRO MONTES JY S.A.S | D23: INSTALACIÓN, MONTAJE Y PUESTA EN OPERACIÓN DEL SISTEMA, INCLUYE: Instalación, montaje y puesta en operación de un sistema fotovoltaico de 1320.8 kWp en DC y 990 kW en AC, en el municipio de Valledupar, Cesar. | E23: $ 195.003.000,00 | F23: $ 37.050.570,00
A24: 14
A25: 15
A26: 16
A27: 17
A28: 18
A29: 19
A30: 20
A31: 21
A32: 22
A33: 23
A34: 24
A35: 25
... A80: 70

Sheet Hoja 1
A1: Nombre de proyecto | B1: Capacidad Instalada

Sheet Listas2
B4: Rol Solicitante principal | D4: Rol Solicitante secundario | F4: Recurso Energético - Tipo de FNCE Biomasa | H4: Tecnología - Tipo de FNCE Biomasa | J4: Departamentos
B5: Dueño del proyecto | D5: Entidad Bancaria | F5: Bagazo | H5: Biogás
D6: Instalador | F6: Biogás | H6: Gasificación | J6: AMAZONAS
D7: Importador | F7: Calor Residual | H7: Pirolización | J7: ANTIOQUIA
D8: Otro | F8: Repoblaciones Residuales Energéticas | H8: Cultivos_energéticos | J8: ARAUCA
F9: Residuos Agrícolas (desechos de los cultivos) | H9: Generación_cogeneración | J9: ARCHIPIELAGO DE SAN ANDRES PROVIDENCIA Y SANTA CATALINA
B10: Tipo de Generador | F10: Residuos Pecuarios (excremento de los animales) | J10: ATLANTICO
B11: Autogenerador | D11: Niveles de tensión | F11: Residuos Sólidos Urbanos (orgánicos) | J11: BOGOTA D.C.
B12: Cogenerador | D12: Mayor o igual a 220 kV. | F12: Sistemas de Acopio de Biomasa | J12: BOLÍVAR
B13: Generador | D13: Nivel 4: mayor o igual a 57.5 kV y menor a 220 kV. | F13: Otro | J13: BOYACÁ
D14: Nivel 3: mayor o igual a 30 kV y menor a 57.5 kV. | J14: CALDAS
D15: Nivel 2: mayor o igual a 1 kV y menor a 30 kV. | J15: CAQUETÁ
D16: Nivel 1: menor a 1 kV. | H16: Tecnología - Tipo de FNCE Eólica | J16: CASANARE
H17: Eólica | J17: CAUCA
B18: Tipo de FNCE (Ley 1715 de 2014) | J18: CESAR
B19: Biomasa | D19: Tipo de FNCE | F19: Recurso Energético - Tipo de FNCE Eólica | J19: CHOCÓ
B20: Eólica | D20: Biomasa | F20: Viento | J20: CÓRDOBA
B21: Geotérmica | D21: Eólica | H21: Tecnología - Tipo de FNCE Geotérmica | J21: CUNDINAMARCA
B22: PCH | D22: Geotérmica | H22: Central_de_vapor_seco | J22: GUAINÍA
B23: Solar | D23: PCH | F23: Recurso Energético - Tipo de FNCE Geotérmica | H23: Central_flash | J23: GUAVIARE
D24: Solar | F24: Vapor | H24: Central_de_ciclo_binario | J24: HUILA
J25: LA GUAJIRA
B26: =CONCATENATE("TEC_",'FORMATO 2'!$F$20) -> TEC_Solar | J26: MAGDALENA
B27: =CONCATENATE("REC_",'FORMATO 2'!$F$20) -> REC_Solar | F27: Recurso Energético - Tipo de FNCE PCH | J27: META
D28: Sector | F28: Agua | H28: Tecnología - Tipo de FNCE PCH | J28: NARIÑO
D29: Residencial | H29: Hidráulica | J29: NORTE DE SANTANDER
D30: Industrial | H30: Hidrocinética | J30: PUTUMAYO
D31: Transporte | F31: Recurso Energético - Tipo de FNCE Solar | J31: QUINDIO
D32: Terciario (comercial, público y de servicios) | F32: Sol | J32: RISARALDA
D33: Generación eléctrica | J33: SANTANDER
H34: Tecnología - Tipo de FNCE Solar | J34: SUCRE
F35: Selección | H35: Fotovoltaica | J35: TOLIMA
D36: Unidad de Medida | J36: VALLE DEL CAUCA
F37: X | J37: VAUPÉS
D38: metros | J38: VICHADA
D39: unidad | F39: {='FORMATO 2'!F20:V20} -> Solar | G39: 0 | H39: 0 | I39: 0 | J39: 0 | K39: 0 | L39: 0 | M39: 0 | N39: 0 | O39: 0 | P39: 0 | Q39: 0 | R39: 0 | S39: 0 | T39: 0 | U39: 0 | V39: 0
D40: unidades
D41: Kilogramos
F44: {=IF(G12=Listas!$B$20,tecbio,IF(G12=Listas!$B$21,Listas!H$13:H$14,IF(G12=Listas!$B$22,teceol,IF(G12=Listas!$B$23,tecgeo,IF(G12=Listas!$B$24,tecpch,IF(G12=Listas!$B$25,tecsol,"Seleccionar tipo de tecnología"))))))} -> #NAME?

Sheet Listas
G2: Codigos CIIU
B3: Cumple | G3: 0010 - Asalariado
D4: Preinversión | G4: 0141 - Cria de ganado bovino y bufalino
B5: Cumple | D5: Inversión | G5: 0142- Cría de caballos y otros equinos
B6: No cumple | D6: Operación | G6: 0143- Cría de ovejas y cabras
B7: No aplica | G7: 0144 -Cría de ganado porcino
G8: 0145 -Cría de aves de corra
B9: Resultado | G9: 0149 -Cría de otros animales n.c.p.
D10: SIN | G10: 0150 -Explotación mixta (agrícola y pecuaria)
B11: Favorable | D11: ZNI | G11: 0161 -Actividades de apoyo a la agricultura
B12: Desfavorable | G12: 0162 -Actividades de apoyo a la ganadería
B13: Requiere de información aclaratoria | D13: Si | G13: 0163 -Actividades posteriores a la cosecha
D14: No | G14: 0164 -Tratamiento de semillas para propagación
B15: Cumple | G15: 0170 -Caza ordinaria y mediante trampas y actividades de servicios conexas
G16: 0210 -Silvicultura y otras actividades forestales
B17: Si | G17: 0220- Extracción de madera
B18: No | G18: 0230- Recolección de productos forestales diferentes a la madera
B19: No aplica | G19: 0240- Servicios de apoyo a la silvicultura
G20: 0311- Pesca marítima
G21: 0312- Pesca de agua dulce
G22: 0321- Acuicultura marítima
G23: 0322- Acuicultura de agua dulce
G24: 0510- Extracción de hulla (carbón de piedra)
G25: 0520- Extracción de carbón lignito
G26: 0610- Extracción de petróleo crudo
G27: 0620- Extracción de gas natural
G28: 0710- Extracción de minerales de hierro
G29: 0721- Extracción de minerales de uranio y de torio
G30: 0722- Extracción de oro y otros metales preciosos
G31: 0723- Extracción de minerales de níque
... G483: 9609 - Otras actividades de servicios personales n.c.p.

Sheet Bienes
A1: =CONCATENATE("Bienes_",'FORMATO 2'!$F$20,"_",'FORMATO 2'!$F$23) -> Bienes_Solar_Fotovoltaica
A3: Bienes_Biomasa_Biogás | B3: Bienes_Biomasa_Gasificación | C3: Bienes_Biomasa_Pirolización | D3: Bienes_Biomasa_Cultivos_energéticos | E3: Bienes_Biomasa_Generación_cogeneración | F3: Bienes_Eólica_Eólica | G3: Bienes_Geotérmica_Central_de_vapor_seco | H3: Bienes_Geotérmica_Central_flash | I3: Bienes_Geotérmica_Central_de_ciclo_binario | J3: Bienes_PCH_Hidráulica | K3: Bienes_PCH_Hidrocinética | L3: Bienes_Solar_Fotovoltaica
A4: Biodigestores | B4: Gasificadores | C4: Bunkers (almacenamiento de residuos) | D4: Equipos y componentes para la producción de cultivos energéticos (torre de madereo, skidder, harvester, brazo cargador, carreto cosechador, winche o cabrestante, astillador de madera, tractores, grúas y grapas). | E4: Motores de CI diseñados para operar con biogás o biocombustibles | F4: Equipos LIDAR | G4: Bombas centrífugas, electrosumergibles, de calor geotérmicas | H4: Bombas centrífugas, electrosumergibles, de calor geotérmicas | I4: Bombas centrífugas, electrosumergibles, de calor geotérmicas | J4: Tuberías | K4: Tuberías | L4: Equipos de medición del recurso solar
A5: Digestores y post-digestores | B5: Sistemas de purificación del gas | C5: Trituradoras | D5: Equipos para el sistema de riego y drenaje empleados en el establecimiento de cultivos con propósitos energéticos (tuberías de PVC, CPVC, válvulas, tanques, bombas) | E5: Calderas para operar con biomasa, biogás o sus derivados, asi como equipos para adaptación de calderas para uso con biomasa, biogás o sus derivados | F5: Equipos SODAR | G5: Válvulas | H5: Válvulas | I5: Válvulas | J5: Chimeneas de equilibrio, aliviaderos | K5: Chimeneas de equilibrio, aliviaderos | L5: Seguidores solares
A6: Tanques de almacenamiento. | B6: Turbinas de gas y de vapor | C6: Hornos rotatorios para pirólisis | D6: Equipos para mecanización del terreno y extracción de madera (Subsoladores, rastra, caballoneador, taipa, cortamalezas, sembradora) | E6: Turbinas de condensación para operar con biogás | F6: Torres de medición | G6: Silenciadores | H6: Silenciadores | I6: Silenciadores | J6: Válvulas y compuertas | K6: Válvulas y compuertas | L6: Datalogger
A7: Equipos de medición de producción de biogás y concentración de metano | B7: Generadores de vapor | C7: Cámaras de combustión | D7: Máquinas peletizadoras | E7: Turbinas de contra-presión para operar con biogás | F7: Anemómetros | G7: Desarenadoras | H7: Desarenadoras | I7: Desarenadoras | J7: Turbinas | K7: Turbinas | L7: Estaciones meteorológicas
A8: Equipos para desulfuración de biogás (y remoción de impurezas) | B8: Unidad funcional | C8: Separador magnético | D8: Equipos para la preparación y transformación de biomasa (equipos de torrefacción, secadores de biomasa, maquinas briqueteadoras) | E8: Incineradores de residuos y sus componentes para la recuperación de calor para la tecnología “waste to energy” | F8: Veletas | G8: Tuberías de vapor, salmuera | H8: Tuberías de vapor, salmuera | I8: Tuberías de vapor, salmuera | J8: Turbogeneradores | K8: Turbogeneradores | L8: Unidad funcional
A9: Equipos para remoción de CO2 de biogás (equipos para producción de biometano) | B9: Máquinas peletizadoras | C9: Turbogeneradores | D9: Equipos para el transporte de biomasa (transportadores de tornillo sinfín, elevadores de cangilones, transportadores de cadena Redler, sinfines, transportadores de banda) | E9: Bio-refinerías para transformación de residuos sólidos urbanos en biocombustibles líquidos | F9: Data Logger | G9: Separadores de vapor o de humedad | H9: Separadores de vapor o de humedad | I9: Separadores de vapor o de humedad | J9: Dispositivos de regulación y tubos difusores | K9: Dispositivos de regulación y tubos difusores | L9: Paneles/módulos o celdas fotovoltaicas
A10: Ventiladores / sopladores para flujo de biogás | B10: Equipos para la preparación y transformación de biomasa (equipos de torrefacción, secadores de biomasa, maquinas briqueteadoras) | C10: Calderas | D10: Medidores bidireccionales | E10: Generadores | F10: Estaciones meteorológicas | G10: Tanques de almacenamiento | H10: Tanques de almacenamiento | I10: Tanques de almacenamiento | J10: Bombas y motores | K10: Bombas y motores | L10: Inversores o microinversores (Off Grid, Grid Tie o Híbrido)
A11: Válvulas | B11: Equipos para el transporte de biomasa (transportadores de tornillo sinfín, elevadores de cangilones, transportadores de cadena Redler, sinfines, transportadores de banda) | C11: Filtros de manga | D11: Medidores Inteligentes | E11: Recuperadores de calor | F11: Equipos de alimentación DC/AC | G11: Intercambiadores de calor, evaporadores o condensadores | H11: Intercambiadores de calor, evaporadores o condensadores | I11: Intercambiadores de calor, evaporadores o condensadores | J11: Elementos hidromecánicos | K11: Elementos hidromecánicos | L11: Reguladores o controladores de carga
A12: Trampas: de ácido sulfhídrico, de llama, de agua | B12: Medidores bidireccionales | C12: Catalizadores | D12: Transformadores (de potencia, medida e instrumentación) | E12: Sistemas de pretratamiento de agua | F12: Unidad funcional | G12: Turbinas | H12: Turbinas | I12: Turbinas | J12: Generadores | K12: Generadores | L12: Baterías solares (de ciclo de descarga profunda): Puede ser de plomo-acido, ions de litio, niquel cadmio, u otro.
A13: Calderas | B13: Medidores Inteligentes | C13: Ventiladores | D13: Bóvedas, puertas cortafuego, compuertas de ventilación y sellos cortafuego | E13: Sistemas de tratamiento de gases de chimenea de las calderas | F13: Aerogeneradores (como un todo) | G13: Generadores | H13: Generadores | I13: Generadores | J13: Transformadores de excitación y rectificadores | K13: Transformadores de excitación y rectificadores | L13: Optimizadores
A14: Hornos | B14: Transformadores (de potencia, medida e instrumentación) | C14: Unidad funcional | D14: Celdas AC/DC | E14: Sistemas recuperadores de condensados | F14: Torres de aerogeneradores | G14: Instrumentos de medida de presión (manómetro), temperatura y flujo másico de fluidos y vapor | H14: Instrumentos de medida de presión (manómetro), temperatura y flujo másico de fluidos y vapor | I14: Instrumentos de medida de presión (manómetro), temperatura y flujo másico de fluidos y vapor | J14: Equipos de regulación de tensión, equipo de regulación de velocidad, control, protección y medida | K14: Equipos de regulación de tensión, equipo de regulación de velocidad, control, protección y medida | L14: Bases / marcos / estructuras diseñadas para montar, anclar e instalar paneles
... A30: Alambres y cables en AC | B30: Equipos de monitoreo, control y automatización (no incluye equipos para conexión a internet) | C30: Fusibles y portafusibles | D30: BESS (Sistema de almacenamiento con base en baterías) | E30: Medidores bidireccionales | F30: Interruptores, reconectadores, seccionadores y transferencias automáticas | G30: Instalaciones superficiales para prueba de pozos | H30: Instalaciones superficiales para prueba de pozos | I30: Instalaciones superficiales para prueba de pozos | J30: Interruptores, reconectadores, seccionadores y transferencias automáticas | K30: Interruptores, reconectadores, seccionadores y transferencias automáticas | L30: Canalizaciones: canaletas, tubos, prefabricadas con barras o con cables, ductos subterráneos
A31: Canalizaciones: canaletas, tubos, prefabricadas con barras o con cables, ductos subterráneos | B31: Subestación o Power Station (transformadores, interruptores, seccionadores, trampas de onda, reconectadores, cuchillas, descargadores de sobretensión) | C31: Interruptores, reconectadores, seccionadores y transferencias automáticas | E31: Medidores Inteligentes | F31: Interruptores de baja tensión | G31: Medidores bidireccionales | H31: Medidores bidireccionales | I31: Medidores bidireccionales | J31: Interruptores de baja tensión | K31: Interruptores de baja tensión | L31: Bandejas portacables
A32: Bandejas portacables | B32: BESS (Sistema de almacenamiento con base en baterías) | C32: Interruptores de baja tensión | E32: Transformadores (de potencia, medida e instrumentación) | F32: Dispositivos de protección contra sobretensiones transitorias (DPS), descargadores de rayos, apantallamiento | G32: Medidores Inteligentes | H32: Medidores Inteligentes | I32: Medidores Inteligentes | J32: Dispositivos de protección contra sobretensiones transitorias (DPS), descargadores de rayos, apantallamiento | K32: Dispositivos de protección contra sobretensiones transitorias (DPS), descargadores de rayos, apantallamiento | L32: Barrajes
A33: Barrajes | C33: Dispositivos de protección contra sobretensiones transitorias (DPS), descargadores de rayos, apantallamiento | E33: Bóvedas, puertas cortafuego, compuertas de ventilación y sellos cortafuego | F33: Unidades de potencia ininterrumpida (UPS) | G33: Transformadores (de potencia, medida e instrumentación) | H33: Transformadores (de potencia, medida e instrumentación) | I33: Transformadores (de potencia, medida e instrumentación) | J33: Unidades de potencia ininterrumpida (UPS) | K33: Unidades de potencia ininterrumpida (UPS) | L33: Cajas y conduletas
A34: Cajas y conduletas | C34: Unidades de potencia ininterrumpida (UPS) | E34: Celdas AC/DC | F34: Elementos o equipos para el sistema de puesta a tierra (varillas, mallas, grapas, conectores) | G34: Bóvedas, puertas cortafuego, compuertas de ventilación y sellos cortafuego | H34: Bóvedas, puertas cortafuego, compuertas de ventilación y sellos cortafuego | I34: Bóvedas, puertas cortafuego, compuertas de ventilación y sellos cortafuego | J34: Elementos o equipos para el sistema de puesta a tierra (varillas, mallas, grapas, conectores) | K34: Elementos o equipos para el sistema de puesta a tierra (varillas, mallas, grapas, conectores) | L34: Fusibles y porta fusibles
A35: Fusibles y portafusibles | C35: Elementos o equipos para el sistema de puesta a tierra (varillas, mallas, grapas, conectores) | E35: Contadores | F35: Sistema de monitoreo, control y automatización | G35: Celdas AC/DC | H35: Celdas AC/DC | I35: Celdas AC/DC | J35: Sistema de monitoreo, control y automatización | K35: Sistema de monitoreo, control y automatización | L35: Interruptores, reconectadores, seccionadores y transferencias automáticas
A36: Interruptores, reconectadores, seccionadores y transferencias automáticas | C36: Equipos de monitoreo, control y automatización (no incluye equipos para conexión a internet) | E36: Tableros de baja tensión AC/DC (Incluye los elementos internos) | F36: Subestación o Power Station | G36: Contadores | H36: Contadores | I36: Contadores | J36: Subestación o Power Station | K36: Subestación o Power Station | L36: Interruptores de baja tensión
A37: Interruptores de baja tensión | C37: Subestación o Power Station (transformadores, interruptores, seccionadores, trampas de onda, reconectadores, cuchillas, descargadores de sobretensión) | E37: Alambres y cables en AC | F37: BESS (Sistema de almacenamiento con base en baterías) | G37: Tableros de baja tensión AC/DC (Incluye los elementos internos) | H37: Tableros de baja tensión AC/DC (Incluye los elementos internos) | I37: Tableros de baja tensión AC/DC (Incluye los elementos internos) | J37: BESS (Sistema de almacenamiento con base en baterías) | K37: BESS (Sistema de almacenamiento con base en baterías) | L37: Dispositivos de protección contra sobretensiones transitorias (DPS), descargadores de rayos, apantallamiento
A38: Dispositivos de protección contra sobretensiones transitorias (DPS), descargadores de rayos, apantallamiento | C38: BESS (Sistema de almacenamiento con base en baterías) | E38: Canalizaciones: canaletas, tubos, prefabricadas con barras o con cables, ductos subterráneos | G38: Alambres y cables en AC | H38: Alambres y cables en AC | I38: Alambres y cables en AC | L38: Unidades de potencia ininterrumpida (UPS)
A39: Unidades de potencia ininterrumpida (UPS) | C39: Sistemas de acopio de biomasa | E39: Bandejas portacables | G39: Canalizaciones: canaletas, tubos, prefabricadas con barras o con cables, ductos subterráneos | H39: Canalizaciones: canaletas, tubos, prefabricadas con barras o con cables, ductos subterráneos | I39: Canalizaciones: canaletas, tubos, prefabricadas con barras o con cables, ductos subterráneos | L39: Elementos o equipos para el sistema de puesta a tierra (varillas, mallas, grapas, conectores)
A40: Elementos o equipos para el sistema de puesta a tierra (varillas, mallas, grapas, conectores) | E40: Barrajes | G40: Bandejas portacables | H40: Bandejas portacables | I40: Bandejas portacables | L40: Sistema de monitoreo, control y automatización
A41: Equipos de monitoreo, control y automatización (no incluye equipos para conexión a internet) | E41: Cajas y conduletas | G41: Barrajes | H41: Barrajes | I41: Barrajes | L41: Subestación o Power Station
A42: Subestación o Power Station (transformadores, interruptores, seccionadores, trampas de onda, reconectadores, cuchillas, descargadores de sobretensión) | E42: Fusibles y portafusibles | G42: Cajas y conduletas | H42: Cajas y conduletas | I42: Cajas y conduletas | L42: BESS (Sistema de almacenamiento con base en baterías)
A43: BESS (Sistema de almacenamiento con base en baterías) | E43: Interruptores, reconectadores, seccionadores y transferencias automáticas | G43: Fusibles y porta fusibles | H43: Fusibles y porta fusibles | I43: Fusibles y porta fusibles
E44: Interruptores de baja tensión | G44: Interruptores, reconectadores, seccionadores y transferencias automáticas | H44: Interruptores, reconectadores, seccionadores y transferencias automáticas | I44: Interruptores, reconectadores, seccionadores y transferencias automáticas
E45: Dispositivos de protección contra sobretensiones transitorias (DPS), descargadores de rayos, apantallamiento | G45: Interruptores de baja tensión | H45: Interruptores de baja tensión | I45: Interruptores de baja tensión
E46: Unidades de potencia ininterrumpida (UPS) | G46: Dispositivos de protección contra sobretensiones transitorias (DPS), descargadores de rayos, apantallamiento | H46: Dispositivos de protección contra sobretensiones transitorias (DPS), descargadores de rayos, apantallamiento | I46: Dispositivos de protección contra sobretensiones transitorias (DPS), descargadores de rayos, apantallamiento
E47: Elementos o equipos para el sistema de puesta a tierra (varillas, mallas, grapas, conectores) | G47: Unidades de potencia ininterrumpida (UPS) | H47: Unidades de potencia ininterrumpida (UPS) | I47: Unidades de potencia ininterrumpida (UPS)
E48: Equipos de monitoreo, control y automatización (no incluye equipos para conexión a internet) | G48: Elementos o equipos para el sistema de puesta a tierra (varillas, mallas, grapas, conectores) | H48: Elementos o equipos para el sistema de puesta a tierra (varillas, mallas, grapas, conectores) | I48: Elementos o equipos para el sistema de puesta a tierra (varillas, mallas, grapas, conectores)
E49: Subestación o Power Station (transformadores, interruptores, seccionadores, trampas de onda, reconectadores, cuchillas, descargadores de sobretensión) | G49: Sistema de monitoreo, control y automatización | H49: Sistema de monitoreo, control y automatización | I49: Sistema de monitoreo, control y automatización
E50: BESS (Sistema de almacenamiento con base en baterías) | G50: Subestación o Power Station | H50: Subestación o Power Station | I50: Subestación o Power Station
E51: Grupo Electrógeno de Biogás | G51: BESS (Sistema de almacenamiento con base en baterías) | H51: BESS (Sistema de almacenamiento con base en baterías) | I51: BESS (Sistema de almacenamiento con base en baterías)

Sheet Servicios
A1: =CONCATENATE("Servicios_",'FORMATO 2'!$F$20,"") -> Servicios_Solar
A3: Servicios_Biomasa | B3: Servicios_Eólica | C3: Servicios_Geotérmica | D3: Servicios_PCH | E3: Servicios_Solar
A4: Estudios de valoración de potencial para uso energético de la biomasa | B4: Estudios de valoración de potencial del recurso eólico. | C4: Alquiler equipos y plataformas de perforación para exploración geotérmica y pruebas de producción de pozos geotérmicos | D4: Estudios de valoración de potencial hidráulico | E4: Estudios de valoración de potencial del recurso solar
A5: Estudios ambientales | B5: Estudios ambientales | C5: Toma de fotografías aéreas; imágenes de satélite; etc para elaboración de cartografía | D5: Estudios ambientales | E5: Estudios ambientales
A6: Estudios de conexión. | B6: Estudios de conexión | C6: Estudios de valoración de potencial del recurso geotérmico | D6: Estudios de conexión | E6: Estudios de conexión
A7: Asesoría y consultoría técnica | B7: Asesoría y consultoría técnica | C7: Estudios ambientales | D7: Asesoría y consultoría técnica | E7: Estudios estructurales
A8: Diseño e Ingeniería del sistema | B8: Diseño e Ingeniería del sistema | C8: Estudios de gradiente térmico | D8: Diseño e Ingeniería del sistema | E8: Asesoría y consultoría técnica
A9: Transporte asociado al traslado de componentes al sitio de instalación | B9: Transporte asociado al traslado de componentes al sitio de instalación | C9: Estudios de conexión. | D9: Transporte asociado al traslado de componentes al sitio de instalación | E9: Diseño e ingeniería del sistema
A10: Instalación, montaje y puesta en operación del sistema. | B10: Instalación, montaje y puesta en operación del sistema. | C10: Geología / exploración. Recolección de muestras de roca y ensayos de laboratorio | D10: Instalación, montaje y puesta en operación del sistema. | E10: Transporte asociado al traslado de componentes al sitio de instalación
A11: Construcción de obras civiles y estructurales para el montaje del sistema. | B11: Construcción de obras civiles y estructurales para el montaje del sistema. | C11: Geoquímica / exploración. Recolección de muestras de líquidos y gases y ensayos de laboratorio para análisis de composición química; análisis de isótopos. | D11: Construcción de obras civiles y estructurales para el montaje del sistema. | E11: Instalación, montaje y puesta en operación del sistema.
A12: Preparación / adaptación del terreno para instalación del sistema | B12: Obras civiles y estructurales para efectos de medición del recurso eólico | C12: Geofísica / exploración. Muestreo; procesamiento y análisis de gravimetría; magnetometría; magnetotelúrica y microsismos) | D12: Preparación / adaptación del terreno para instalación del sistema | E12: Construcción de obras civiles y estructurales para el montaje del sistema.
A13: Construcción de digestores; post-digestores y tanques de almacenamiento para proyectos de uso energético de la biomasa | B13: Preparación / adaptación del terreno para instalación del sistema | C13: Asesoría y consultoría técnica | E13: Preparación / adaptación del terreno para instalación del sistema
A14: Construcción de lagunas para proyectos de uso energético de la biomasa | C14: Diseño e Ingeniería del sistema (Incluyendo software especializado) | E14: Certificación RETIE
A15: Construcción de instalaciones de recibo y acopio de biomasa para ser usada con fines energéticos | C15: Instalación, montaje y puesta en operación del sistema.
C16: Construcción de obras civiles y estructurales para el montaje del sistema.
C17: Preparación / adaptación del terreno para instalación del sistema
C18: Transporte asociado al traslado de componentes al sitio de instalación

Sheet Items BT Faltantes
A1: ITEMS MARCADOS COMO "BT" EN PEPC QUE FALTAN EN EL FORMATO 3 DEL "PAPÁ DE LOS FORMATOS"
A2: Estos elementos aparecen marcados con "BT" en la columna BT de la hoja PEPC pero no están registrados en el FORMATO 3 (ni por código Odoo ni por descripción equivalente). Se excluyen servicios (transporte, nacionalización, instalación, pruebas, etc.).
A4: # | B4: Código Odoo | C4: Descripción (de PEPC) | D4: Unidad | E4: Cantidad | F4: Nombre canónico Odoo (si código existe)
A5: 1 | B5: P01036 | C5: Transformador de potencia 17.5kV 13.2/120 500VA | D5: Und | E5: 1 | F5: Nombre Odoo: [P01036] Transformador Potencia 1500 kVA Dyn5 13200/800 V
A6: 2 | B6: P00609 | C6: Gabinete, 2 borneras, 2 modem telemedida | D6: Und | E6: 1 | F6: Nombre Odoo: [P00609] Gabinete
A7: 3 | B7: P00364 | C7: Suministro cable XLPE 1/0 Pantalla en hilo 100% Aluminio 15kV (x3 terna) | D7: m | E7: 15 | F7: Nombre Odoo: [P00364] Cable XLPE Pantalla en Cinta (35 KV, 1/0 AWG) - 35 KV / 1/0 AWG
A8: 4 | B8: P00320 | C8: Suministro cable ecológico ASCR | D8: m | E8: 445 | F8: Nombre Odoo: [P00320] Cable Ecológico ASCR (15 KV, 1/0 AWG) - 15 KV / 1/0 AWG
A9: 5 | B9: P00572 | C9: Estación meteorológica | D9: Und | E9: 1 | F9: Nombre Odoo: [P00572] Estación Metereológica
A10: 6 | B10: Sin código | C10: CABLE 500 kcmil Al RHW 800V (Fases inversores 249 kW - Tablero FV) | D10: m | E10: 2000
A11: 7 | B11: Sin código | C11: CABLE 12 AWG Cu 600V (SSAA) | D11: m | E11: 300
A12: 8 | B12: Sin código | C12: Par hembra y macho de MC4 | D12: Und | E12: 200
A13: 9 | B13: Sin código | C13: Tubo PVC DB Liso 4" x 6M | D13: Und | E13: 400
A14: 10 | B14: Sin código | C14: Tubo EMT 3/4" x 6m | D14: Und | E14: 6
A15: 11 | B15: Sin código | C15: Tubo anillado de poliamida Interflex Nylofix AGT-12N (paq x 30m) | D15: Und | E15: 8
A16: 12 | B16: Sin código | C16: Tubo PVC BD Liso 1/2" x 3m | D16: Und | E16: 100
A17: 13 | B17: Sin código | C17: Coraza Americana 1" | D17: m | E17: 10
A18: 14 | B18: Sin código | C18: Puntas captadoras de apantallamiento | D18: Und | E18: 4
